Workbook

Sheet Cover Page
D3: RAMID Version 1.0
B16: Version | C16: Created By | D16: History Details | E16: Date | F16: Reviewed By | G16: Approved By

Sheet Summary
A2: RAMID Checklist
A3: Department:
A4: Portfolio Lead:
A6: Checklist Question | B6: Mar, 2023 | C6: Apr, 2023 | D6: May, 2023 | E6: Jun, 2023 | F6: Jul, 2023 | G6: Aug, 2023 | H6: Sep, 2023 | I6: Oct, 2023 | J6: Nov, 2023 | K6: Dec, 2023 | L6: Jan, 2024 | M6: Feb, 2024 | N6: Mar, 2024 | O6: Apr, 2024 | P6: May, 2024 | Q6: Jun, 2024 | R6: Jul, 2024 | S6: Aug, 2024 | T6: Sep, 2024 | U6: Oct, 2024 | V6: Nov, 2024 | W6: Dec, 2024
A7: Team Churn Rate is discussed | D7: Yes | E7: Yes | F7: Yes | G7: Yes | H7: Yes | I7: Yes | J7: Yes | K7: Yes | L7: Yes | M7: Yes
A8: Pulse Survey Feedback is discussed | D8: No | E8: No | F8: No | G8: No | H8: No | I8: No | J8: Yes | K8: Yes | L8: Yes | M8: Yes
A9: Audit Violations are discussed | C9: Yes | D9: Yes | E9: Yes | F9: No | G9: Yes | H9: Yes | I9: Yes | J9: Yes | K9: Yes | L9: Yes | M9: Yes
A10: KPI Score is analyzed in the meeting | D10: No | E10: No | F10: No | G10: Yes | H10: Yes | I10: Yes | J10: Yes | K10: Yes | L10: Yes | M10: Yes

Sheet Risks
A1: Risks
A2: Sr. No | B2: Risk Description | C2: Impact Description | D2: Mitigation Strategy | E2: Impact | F2: Probability | G2: Severity (Calculated) | H2: Owner | I2: Date Raised | J2: Date Closed | K2: Status | L2: Comments
A3: 1 | B3: US team provided estimates on new contract, but due to existing thread not completed and spilovers. We are unable to allocate team to new threads. | C3: New threads can be impacted and can not be started on time. There are high chances team would not be able to complete the contract on time. | D3: after discussion with all stakesholders, it was decided we will not inform the client that we have made the mistake in estimating and we can not deliver all modules, Instread we will start the work and in the end of contract if we are unable to complete we will take it as retrospectivly. We have added 4 new people to the team | E3: High | F3: High | G3: =IF(E3 = "High", VLOOKUP(F3,'Risk Chart'!$B$2:$C$6,2),IF(E3 = "Very High", VLOOKUP(F3,'Risk Chart'!$B$17:$C$21,2),IF(E3 = "Very Low", VLOOKUP(F3,'Risk Chart'!$B$22:$C$26,2),IF(E3 = "Low", VLOOKUP(F3,'Risk Chart'!$B$7:$C$11,2),IF(E3 = "Medium", VLOOKUP(F3,'Risk Chart'!$B$12:$C$16,2), ""))))) -> High | H3: Saqib | I3: 44570 | J3: 20/9/2022 | K3: Closed
A4: 2 | B4: There is no GDC PM after moving saqib to US. also there is load on Atieq to manage 5 team in GDC. | C4: This can impact the team performance. | D4: after discussion with all stakeholders we included new Architect instread of new PMin the team. teams are divided across three architects to share the burden | E4: High | F4: High | G4: =IF(E4 = "High", VLOOKUP(F4,'Risk Chart'!$B$2:$C$6,2),IF(E4 = "Very High", VLOOKUP(F4,'Risk Chart'!$B$17:$C$21,2),IF(E4 = "Very Low", VLOOKUP(F4,'Risk Chart'!$B$22:$C$26,2),IF(E4 = "Low", VLOOKUP(F4,'Risk Chart'!$B$7:$C$11,2),IF(E4 = "Medium", VLOOKUP(F4,'Risk Chart'!$B$12:$C$16,2), ""))))) -> High | H4: saqib | I4: 44843 | J4: 20/9/2022 | K4: Closed
A5: 3 | B5: Client expecting production release of all modules | C5: this is major concern from team and already communicate to all stakehodlers | D5: account team has assured there is no such understanding with client and it will only be dev completion end of this contract | E5: High | F5: High | G5: =IF(E5 = "High", VLOOKUP(F5,'Risk Chart'!$B$2:$C$6,2),IF(E5 = "Very High", VLOOKUP(F5,'Risk Chart'!$B$17:$C$21,2),IF(E5 = "Very Low", VLOOKUP(F5,'Risk Chart'!$B$22:$C$26,2),IF(E5 = "Low", VLOOKUP(F5,'Risk Chart'!$B$7:$C$11,2),IF(E5 = "Medium", VLOOKUP(F5,'Risk Chart'!$B$12:$C$16,2), ""))))) -> High | H5: saqib | I5: 44843 | K5: Closed
A6: 4 | B6: While analyzing drug app package for bu, it is identified that the code available in repo is different from the one which is deployed on production. hence package is being created differently. We shared the concern with Shaun (Walmart) and he directed to discuss with GTP team to reverse engineer production code to compare and see the difference so that we can implement same business logic. We have created Jira issue for GTP team on 7th October but having received any response from GTP. We have also shared the concerns and expected blocker with Shaun as well. | C6: Team wouldn't be able to start development (Planned 26th October) of package creation by bu Id which will lead one business area for package creation unintended and cause overall delay in data distribution delivery timeline | D6: Shaun/Walmart team needs to intervene, get and share the latest code to enable development team start working on package creation | E6: High | F6: High | G6: =IF(E6 = "High", VLOOKUP(F6,'Risk Chart'!$B$2:$C$6,2),IF(E6 = "Very High", VLOOKUP(F6,'Risk Chart'!$B$17:$C$21,2),IF(E6 = "Very Low", VLOOKUP(F6,'Risk Chart'!$B$22:$C$26,2),IF(E6 = "Low", VLOOKUP(F6,'Risk Chart'!$B$7:$C$11,2),IF(E6 = "Medium", VLOOKUP(F6,'Risk Chart'!$B$12:$C$16,2), ""))))) -> High | H6: atieq | I6: 44852 | K6: Closed | L6: Data distribution Package creation
A7: =IF(B6="","",A6+1) -> 5 | B7: No QA available for MDDB Search thread and testing will be pending till then and if any bug fixes or problem may be seen. Also there are no test cases writing and automation work can be done and may have few things which are missing as per QA perspective. | C7: MDDB APIs and UI would not be properly tested in time and may show up issues later time and developers need to re-engage at time of testing. Secondly as we wont have QA test cases and not synched with client there could be things which are not covered in development. | D7: Need QA resource ASAP | E7: High | F7: High | G7: =IF(E7 = "High", VLOOKUP(F7,'Risk Chart'!$B$2:$C$6,2),IF(E7 = "Very High", VLOOKUP(F7,'Risk Chart'!$B$17:$C$21,2),IF(E7 = "Very Low", VLOOKUP(F7,'Risk Chart'!$B$22:$C$26,2),IF(E7 = "Low", VLOOKUP(F7,'Risk Chart'!$B$7:$C$11,2),IF(E7 = "Medium", VLOOKUP(F7,'Risk Chart'!$B$12:$C$16,2), ""))))) -> High | H7: Khurram | I7: 44839 | K7: Closed | L7: MDDB Search/GPI
A8: =IF(B7="","",A7+1) -> 6 | B8: No Senior UI Developer engaged yet which is slowing down the progress with fresh resource and there is no concrete timeline when this will be finished and quality may suffer. | C8: It can delay the timeline. | D8: Need Senior UI Developer | E8: High | F8: High | G8: =IF(E8 = "High", VLOOKUP(F8,'Risk Chart'!$B$2:$C$6,2),IF(E8 = "Very High", VLOOKUP(F8,'Risk Chart'!$B$17:$C$21,2),IF(E8 = "Very Low", VLOOKUP(F8,'Risk Chart'!$B$22:$C$26,2),IF(E8 = "Low", VLOOKUP(F8,'Risk Chart'!$B$7:$C$11,2),IF(E8 = "Medium", VLOOKUP(F8,'Risk Chart'!$B$12:$C$16,2), ""))))) -> High | H8: Khurram | I8: 44839 | K8: Closed | L8: MDDB Search/GPI
A9: =IF(B8="","",A8+1) -> 7 | B9: Due to the unavailability of valid packages in the production environment, the team is unable to start development for the drug-add-by-item-ids endpoint | C9: Team is blocked on package development for this endpoint and waiting for Shaun's reply to proceed with | D9: Shaun to share sample packages to do analysis and resume development | E9: High | F9: High | G9: High | H9: atieq | I9: 44854 | K9: Closed | L9: Data distribution Package creation
A10: =IF(B9="","",A9+1) -> 8 | B10: In MDDB Search, the addition of new workflows related to add new products/items can impact the timeline | C10: Teams needs to work on discovery for these new workflows and connect with client on any queries before starting implementation | D10: We have communicated the impact this can cause on our timeline with the client | E10: High | F10: High | G10: =IF(E10 = "High", VLOOKUP(F10,'Risk Chart'!$B$2:$C$6,2),IF(E10 = "Very High", VLOOKUP(F10,'Risk Chart'!$B$17:$C$21,2),IF(E10 = "Very Low", VLOOKUP(F10,'Risk Chart'!$B$22:$C$26,2),IF(E10 = "Low", VLOOKUP(F10,'Risk Chart'!$B$7:$C$11,2),IF(E10 = "Medium", VLOOKUP(F10,'Risk Chart'!$B$12:$C$16,2), ""))))) -> High | H10: Khurram | I10: 44901 | K10: Closed | L10: MDDB Search/GPI
A11: =IF(B10="","",A10+1) -> 9 | B11: SOW Renewal and VDI expiry | C11: VDI will close on end of Feb | D11: SOW discussion are going on and we are keeping and eye on date and adam will help to get it renewed and process int he system on priority. | E11: Medium | F11: Medium | G11: =IF(E11 = "High", VLOOKUP(F11,'Risk Chart'!$B$2:$C$6,2),IF(E11 = "Very High", VLOOKUP(F11,'Risk Chart'!$B$17:$C$21,2),IF(E11 = "Very Low", VLOOKUP(F11,'Risk Chart'!$B$22:$C$26,2),IF(E11 = "Low", VLOOKUP(F11,'Risk Chart'!$B$7:$C$11,2),IF(E11 = "Medium", VLOOKUP(F11,'Risk Chart'!$B$12:$C$16,2), ""))))) -> Medium | H11: Saqib | I11: 15/12/2022 | K11: Closed | L11: SOW
A12: =IF(B11="","",A11+1) -> 10 | B12: Production Deployment as per the plan seems too tight to achieve in given timelines | C12: We may have to work beyond billable MO4 timelines | D12: Team is discussing how to start deployment activities in advance and how to achieve more parallelism Action: We need to make plan for Store side installations | E12: High | F12: High | G12: =IF(E12 = "High", VLOOKUP(F12,'Risk Chart'!$B$2:$C$6,2),IF(E12 = "Very High", VLOOKUP(F12,'Risk Chart'!$B$17:$C$21,2),IF(E12 = "Very Low", VLOOKUP(F12,'Risk Chart'!$B$22:$C$26,2),IF(E12 = "Low", VLOOKUP(F12,'Risk Chart'!$B$7:$C$11,2),IF(E12 = "Medium", VLOOKUP(F12,'Risk Chart'!$B$12:$C$16,2), ""))))) -> High | H12: Saqib | I12: 15/05/2023 | K12: Closed | L12: Action: We need to make plan for Store side installations
A13: =IF(B12="","",A12+1) -> 11 | B13: SOW Renewal and VDI expiry | C13: Team members will not be able to access the vdi and cannot continue work | D13: Team will upload their documents to one drive. | E13: High | F13: Very High | G13: =IF(E13 = "High", VLOOKUP(F13,'Risk Chart'!$B$2:$C$6,2),IF(E13 = "Very High", VLOOKUP(F13,'Risk Chart'!$B$17:$C$21,2),IF(E13 = "Very Low", VLOOKUP(F13,'Risk Chart'!$B$22:$C$26,2),IF(E13 = "Low", VLOOKUP(F13,'Risk Chart'!$B$7:$C$11,2),IF(E13 = "Medium", VLOOKUP(F13,'Risk Chart'!$B$12:$C$16,2), ""))))) -> Very High | H13: Saqib | I13: 23/05/2023 | K13: Closed | L13: SOW - 13/06: VDI extended
A14: =IF(B13="","",A13+1) -> 12 | B14: Sadia resigned. So loss of a senior developer can have its immediate negative impact on the productivity/loss of knowledge experience. | C14: Reduced Dev Capacity/Loss of Experience | D14: Mustafa A/Talha are taking KT sessions for Prescriber | E14: Medium | F14: High | G14: =IF(E14 = "High", VLOOKUP(F14,'Risk Chart'!$B$2:$C$6,2),IF(E14 = "Very High", VLOOKUP(F14,'Risk Chart'!$B$17:$C$21,2),IF(E14 = "Very Low", VLOOKUP(F14,'Risk Chart'!$B$22:$C$26,2),IF(E14 = "Low", VLOOKUP(F14,'Risk Chart'!$B$7:$C$11,2),IF(E14 = "Medium", VLOOKUP(F14,'Risk Chart'!$B$12:$C$16,2), ""))))) -> High | H14: Ayyaz | I14: 23-05-23 | J14: 45208 | K14: Closed | L14: KT document prepared by Sadia for Talha we have recurited Senior QA
A15: =IF(B14="","",A14+1) -> 13 | B15: Mockups Pending for Medguides, Drug History NDC linking, Online Item File, GPI | C15: Scope, Timeline​ | D15: Share the list of required mockups and Rachael has shared the priority as well.​ | E15: Medium | F15: Medium | G15: =IF(E15 = "High", VLOOKUP(F15,'Risk Chart'!$B$2:$C$6,2),IF(E15 = "Very High", VLOOKUP(F15,'Risk Chart'!$B$17:$C$21,2),IF(E15 = "Very Low", VLOOKUP(F15,'Risk Chart'!$B$22:$C$26,2),IF(E15 = "Low", VLOOKUP(F15,'Risk Chart'!$B$7:$C$11,2),IF(E15 = "Medium", VLOOKUP(F15,'Risk Chart'!$B$12:$C$16,2), ""))))) -> Medium | H15: Saqib | I15: 15/05/2023 | J15: 45285 | K15: Closed | L15: we are actively chasing Walmart PO to resolve this
A16: =IF(B15="","",A15+1) -> 14 | B16: Cost and reorder new Mockups based on wireframes | C16: Scope, Timeline​ | D16: Cost and reorder Mockups have been assigned high priority. | E16: Medium | F16: Medium | G16: =IF(E16 = "High", VLOOKUP(F16,'Risk Chart'!$B$2:$C$6,2),IF(E16 = "Very High", VLOOKUP(F16,'Risk Chart'!$B$17:$C$21,2),IF(E16 = "Very Low", VLOOKUP(F16,'Risk Chart'!$B$22:$C$26,2),IF(E16 = "Low", VLOOKUP(F16,'Risk Chart'!$B$7:$C$11,2),IF(E16 = "Medium", VLOOKUP(F16,'Risk Chart'!$B$12:$C$16,2), ""))))) -> Medium | H16: Saqib | I16: 15/05/2023 | J16: 45285 | K16: Closed | L16: we are actively chasing Walmart PO to resolve this
A17: 15 | B17: Clarus One - (Cost & Reorder) - PRD, Mockup and API Integration Pending from client side. Late APIs and clarfication on certain issues from thirdpary caused this to be delayed. We are on Track to finish the work as per the requirements on 12 Jan However late UAT completion can cause a Risk if any thing identified during the UAT. | C17: Timeline | D17: 1) Starting with what ever we got from PRD/Mockup/API instead of wating for all of it and start in one go. 2) Esclating this situation with client to get ClarusOne API integration on priority | E17: Medium | F17: Medium | G17: =IF(E17 = "High", VLOOKUP(F17,'Risk Chart'!$B$2:$C$6,2),IF(E17 = "Very High", VLOOKUP(F17,'Risk Chart'!$B$17:$C$21,2),IF(E17 = "Very Low", VLOOKUP(F17,'Risk Chart'!$B$22:$C$26,2),IF(E17 = "Low", VLOOKUP(F17,'Risk Chart'!$B$7:$C$11,2),IF(E17 = "Medium", VLOOKUP(F17,'Risk Chart'!$B$12:$C$16,2), ""))))) -> Medium | H17: Ayyaz | I17: 31/08/2023 | J17: 45209 | K17: Closed | L17: we had a meeting for ClarusOne API on 22 Sept. 22 Oct: The ClarusOne Manager was not fully prepared to answer the questions and was not able to provide the API access to us. we have raised this as High Risk to WM. 04 Oct: Richard (ClarusOne) will come back to us today on this. Business impact ? 01 Dec: Access is available. we have found some data discrepancies. Atieq has already shared the it with walmart and clarus one team. waiting for their reply 13-15 Dec: we have had multiple meetings on data flow issues and have esclated this to Richard in a recent email. waiting for the reply. Its a job which generates clarusOne report. We are not geting any data to create report. 02 Jan: We are on track to complete dev for this on 12 Jan. UAT completetion and anything comming out of UAT could cause Risk
A18: =IF(B17="","",A17+1) -> 16 | B18: OIF - 02 October UAT Start There are few questions with pending answers that we need to continue "Why we compare Vendor Stock Number with NDC? Why we are not getting NDC From IQS. Sindhoor/Nathan suggested to go back to IQS on this" | C18: Timeline | D18: 1) We are actively esclating the issue to WM to get us the directions on the pending items 2) We are scheduling the meeting with the relevant stakeholders + IQS to get closure on this ASAP. we need to align both Fahid Sb and Saqib | E18: Medium | F18: Medium | G18: =IF(E18 = "High", VLOOKUP(F18,'Risk Chart'!$B$2:$C$6,2),IF(E18 = "Very High", VLOOKUP(F18,'Risk Chart'!$B$17:$C$21,2),IF(E18 = "Very Low", VLOOKUP(F18,'Risk Chart'!$B$22:$C$26,2),IF(E18 = "Low", VLOOKUP(F18,'Risk Chart'!$B$7:$C$11,2),IF(E18 = "Medium", VLOOKUP(F18,'Risk Chart'!$B$12:$C$16,2), ""))))) -> Medium | H18: Ayyaz | I18: 31/08/2023 | J18: 45209 | K18: Closed | L18: 22 Sept: Only PRD and mockup update pending
A19: =IF(B18="","",A18+1) -> 17 | B19: GPI - 21 Sept UAT Start There are few questions with pending answers that we need to continue There are 14 exception types in production database that are not visible in Legacy UI, Business want's to see them in Carbon Need exception values information against some of the exception types | C19: Timeline | D19: 1) We are actively esclating the issue to WM to get us the directions on the pending items 2) We are meeting with the wider audience/stakeholders + Tina to get closure on this ASAP. | E19: Medium | F19: Medium | G19: =IF(E19 = "High", VLOOKUP(F19,'Risk Chart'!$B$2:$C$6,2),IF(E19 = "Very High", VLOOKUP(F19,'Risk Chart'!$B$17:$C$21,2),IF(E19 = "Very Low", VLOOKUP(F19,'Risk Chart'!$B$22:$C$26,2),IF(E19 = "Low", VLOOKUP(F19,'Risk Chart'!$B$7:$C$11,2),IF(E19 = "Medium", VLOOKUP(F19,'Risk Chart'!$B$12:$C$16,2), ""))))) -> Medium | H19: Ayyaz | I19: 31/08/2023 | J19: 45209 | K19: Closed | L19: 22 Sept: We got our answers from client
A20: =IF(B19="","",A19+1) -> 18 | B20: Kafka Messages for Data Distribution - 02 Oct Prod Roll Out Kafka Team is still maintaining the same stance that we will have to design a solution with multiple topics/or use Message Proxy Service. This means we have change our implementation which can have implications on Timelines and we will need another sign off on UAT. | C20: Timeline | D20: We escalated this issue with Shaun and got approval to do POC for 5K users on Secure Dedicated Cluster (same approach as CPC team is using) and we can use JMeter on local machines to do the testing | E20: Medium | F20: Medium | G20: =IF(E20 = "High", VLOOKUP(F20,'Risk Chart'!$B$2:$C$6,2),IF(E20 = "Very High", VLOOKUP(F20,'Risk Chart'!$B$17:$C$21,2),IF(E20 = "Very Low", VLOOKUP(F20,'Risk Chart'!$B$22:$C$26,2),IF(E20 = "Low", VLOOKUP(F20,'Risk Chart'!$B$7:$C$11,2),IF(E20 = "Medium", VLOOKUP(F20,'Risk Chart'!$B$12:$C$16,2), ""))))) -> Medium | H20: Ayyaz | I20: 31/08/2023 | J20: 45209 | K20: Closed | L20: 22 Sept: We have completed and shared POC We should have put this assumption that 1 topic will serve 5000 consumers in UAT Signoff
A21: 19 | B21: Connexus application not working on Test Stores. | C21: Timeline | D21: we have raised support ticket for WM. we have got a response that we will get a new Test Store Box | E21: Medium | F21: Medium | G21: =IF(E21 = "High", VLOOKUP(F21,'Risk Chart'!$B$2:$C$6,2),IF(E21 = "Very High", VLOOKUP(F21,'Risk Chart'!$B$17:$C$21,2),IF(E21 = "Very Low", VLOOKUP(F21,'Risk Chart'!$B$22:$C$26,2),IF(E21 = "Low", VLOOKUP(F21,'Risk Chart'!$B$7:$C$11,2),IF(E21 = "Medium", VLOOKUP(F21,'Risk Chart'!$B$12:$C$16,2), ""))))) -> Medium | H21: Ayyaz | I21: 25/09/2023 | J21: 45209 | K21: Closed | L21: 04 Oct: Support has recently acknowledged that their is a problem with test boxes and they will provide us a new Test Store with working Connexus - ETA with in a week ?
A22: =IF(B21="","",A21+1) -> 20 | B22: Requirement Changes listed in Issues Tab Row# 11-19 | C22: Timeline | D22: New Production Timelines to be agreed post requirement analysis and estimations | E22: High | F22: High | G22: =IF(E22 = "High", VLOOKUP(F22,'Risk Chart'!$B$2:$C$6,2),IF(E22 = "Very High", VLOOKUP(F22,'Risk Chart'!$B$17:$C$21,2),IF(E22 = "Very Low", VLOOKUP(F22,'Risk Chart'!$B$22:$C$26,2),IF(E22 = "Low", VLOOKUP(F22,'Risk Chart'!$B$7:$C$11,2),IF(E22 = "Medium", VLOOKUP(F22,'Risk Chart'!$B$12:$C$16,2), ""))))) -> High | H22: Ayyaz/Saqib | I22: 45231 | J22: 45261 | K22: Closed | L22: New Requirements and issues discovered by WM Team and are now assigned to RDM MO team for implementation However for most of the items WM still need us to provide clear requirements/Mockups/UX etc 01 Dec: Work is in Progress for the change requests new Production Date is 15 Jan
A23: =IF(B22="","",A22+1) -> 21 | B23: Carbon UI deployment is failing on Staging so our current carbon UI CRQ is on pause. This is due to recent ask from WM to include Carbon UI into SOX. This could cause delay in SoftLaunch plan | C23: This could cause delay in SoftLaunch plan | D23: Hassan Amjad engaged colin yesterday night on this. Hassan Amjad and Ramzan are investigating the issue. | E23: High | F23: High | G23: =IF(E23 = "High", VLOOKUP(F23,'Risk Chart'!$B$2:$C$6,2),IF(E23 = "Very High", VLOOKUP(F23,'Risk Chart'!$B$17:$C$21,2),IF(E23 = "Very Low", VLOOKUP(F23,'Risk Chart'!$B$22:$C$26,2),IF(E23 = "Low", VLOOKUP(F23,'Risk Chart'!$B$7:$C$11,2),IF(E23 = "Medium", VLOOKUP(F23,'Risk Chart'!$B$12:$C$16,2), ""))))) -> High | H23: Hassan Amjad | I23: 45307 | J23: 45316 | K23: Closed
A24: =IF(B23="","",A23+1) -> 22 | B24: Last minute of UI CRQ we were told to move UI to SOX. Colin has categorically said that due to late minute inclusion of SOX he won't allow prod deployment without presence of wcnp support person in the zoom call during deployment. | C24: Most probably a new CRQ will be needed for sox migration of carbon UI. If WCNP resource is not engaged on time it can delay the CRQ deployment | D24: we need to engage WCNP folks as we have a valid CRQ and do the deployment. We already Have list of steps needed for this deployment. one of backend resources who has been doing wcnp deployment should be available along the go. | E24: Low | F24: Low | G24: High | H24: Hassan Amjad | I24: 45307 | J24: 45316 | K24: Closed
A25: =IF(B24="","",A24+1) -> 23 | B25: For Production Release we need to disable legacy application menus/services We need to understand the BE package distribution code in Legacy Application w.r.t to disabling the sending of Package to store side. Changes to legacy application can result into unseen issues. Especially from deployment perspective we need more information from Client | C25: Any unseen issues esp during deployment can delay the final release in first week of Feb 2024 | D25: We will have to do a proper analysis of the change its impact also how to do deployment. | E25: High | F25: Low | G25: =IF(E25 = "High", VLOOKUP(F25,'Risk Chart'!$B$2:$C$6,2),IF(E25 = "Very High", VLOOKUP(F25,'Risk Chart'!$B$17:$C$21,2),IF(E25 = "Very Low", VLOOKUP(F25,'Risk Chart'!$B$22:$C$26,2),IF(E25 = "Low", VLOOKUP(F25,'Risk Chart'!$B$7:$C$11,2),IF(E25 = "Medium", VLOOKUP(F25,'Risk Chart'!$B$12:$C$16,2), ""))))) -> Medium | H25: Owner 1 | I25: 45307 | K25: Closed | L25: FE application will be shut off by the client team and BE services will be shut down by our team
A26: =IF(B25="","",A25+1) -> 24 | B26: Ops team who is responsible to restart/updates the inactive stores has not responded back to our request for an on boarding session of the new system. This session is crucial for them to smoothly execute their current responsibilities | C26: Failure to timely restart the stores and keep them inactive may result in missing critical updates generated by the system. | D26: To address this potential risk, Our team is proactively working on developing a script to restart the inactive stores independently | E26: High | F26: Low | G26: =IF(E26 = "High", VLOOKUP(F26,'Risk Chart'!$B$2:$C$6,2),IF(E26 = "Very High", VLOOKUP(F26,'Risk Chart'!$B$17:$C$21,2),IF(E26 = "Very Low", VLOOKUP(F26,'Risk Chart'!$B$22:$C$26,2),IF(E26 = "Low", VLOOKUP(F26,'Risk Chart'!$B$7:$C$11,2),IF(E26 = "Medium", VLOOKUP(F26,'Risk Chart'!$B$12:$C$16,2), ""))))) -> Medium | H26: Owner 2 | I26: 45322 | K26: Closed | L26: Our Team will be taking care of this activity as Ops team refused to do this.
G27: =IF(E27 = "High", VLOOKUP(F27,'Risk Chart'!$B$2:$C$6,2),IF(E27 = "Very High", VLOOKUP(F27,'Risk Chart'!$B$17:$C$21,2),IF(E27 = "Very Low", VLOOKUP(F27,'Risk Chart'!$B$22:$C$26,2),IF(E27 = "Low", VLOOKUP(F27,'Risk Chart'!$B$7:$C$11,2),IF(E27 = "Medium", VLOOKUP(F27,'Risk Chart'!$B$12:$C$16,2), "")))))
A28: =IF(B27="","",A27+1) | G28: =IF(E28 = "High", VLOOKUP(F28,'Risk Chart'!$B$2:$C$6,2),IF(E28 = "Very High", VLOOKUP(F28,'Risk Chart'!$B$17:$C$21,2),IF(E28 = "Very Low", VLOOKUP(F28,'Risk Chart'!$B$22:$C$26,2),IF(E28 = "Low", VLOOKUP(F28,'Risk Chart'!$B$7:$C$11,2),IF(E28 = "Medium", VLOOKUP(F28,'Risk Chart'!$B$12:$C$16,2), "")))))
A29: =IF(B28="","",A28+1) | G29: =IF(E29 = "High", VLOOKUP(F29,'Risk Chart'!$B$2:$C$6,2),IF(E29 = "Very High", VLOOKUP(F29,'Risk Chart'!$B$17:$C$21,2),IF(E29 = "Very Low", VLOOKUP(F29,'Risk Chart'!$B$22:$C$26,2),IF(E29 = "Low", VLOOKUP(F29,'Risk Chart'!$B$7:$C$11,2),IF(E29 = "Medium", VLOOKUP(F29,'Risk Chart'!$B$12:$C$16,2), "")))))
A30: =IF(B29="","",A29+1) | G30: =IF(E30 = "High", VLOOKUP(F30,'Risk Chart'!$B$2:$C$6,2),IF(E30 = "Very High", VLOOKUP(F30,'Risk Chart'!$B$17:$C$21,2),IF(E30 = "Very Low", VLOOKUP(F30,'Risk Chart'!$B$22:$C$26,2),IF(E30 = "Low", VLOOKUP(F30,'Risk Chart'!$B$7:$C$11,2),IF(E30 = "Medium", VLOOKUP(F30,'Risk Chart'!$B$12:$C$16,2), "")))))
G31: =IF(E31 = "High", VLOOKUP(F31,'Risk Chart'!$B$2:$C$6,2),IF(E31 = "Very High", VLOOKUP(F31,'Risk Chart'!$B$17:$C$21,2),IF(E31 = "Very Low", VLOOKUP(F31,'Risk Chart'!$B$22:$C$26,2),IF(E31 = "Low", VLOOKUP(F31,'Risk Chart'!$B$7:$C$11,2),IF(E31 = "Medium", VLOOKUP(F31,'Risk Chart'!$B$12:$C$16,2), "")))))
G32: =IF(E32 = "High", VLOOKUP(F32,'Risk Chart'!$B$2:$C$6,2),IF(E32 = "Very High", VLOOKUP(F32,'Risk Chart'!$B$17:$C$21,2),IF(E32 = "Very Low", VLOOKUP(F32,'Risk Chart'!$B$22:$C$26,2),IF(E32 = "Low", VLOOKUP(F32,'Risk Chart'!$B$7:$C$11,2),IF(E32 = "Medium", VLOOKUP(F32,'Risk Chart'!$B$12:$C$16,2), "")))))
G33: =IF(E33 = "High", VLOOKUP(F33,'Risk Chart'!$B$2:$C$6,2),IF(E33 = "Very High", VLOOKUP(F33,'Risk Chart'!$B$17:$C$21,2),IF(E33 = "Very Low", VLOOKUP(F33,'Risk Chart'!$B$22:$C$26,2),IF(E33 = "Low", VLOOKUP(F33,'Risk Chart'!$B$7:$C$11,2),IF(E33 = "Medium", VLOOKUP(F33,'Risk Chart'!$B$12:$C$16,2), "")))))
G34: =IF(E34 = "High", VLOOKUP(F34,'Risk Chart'!$B$2:$C$6,2),IF(E34 = "Very High", VLOOKUP(F34,'Risk Chart'!$B$17:$C$21,2),IF(E34 = "Very Low", VLOOKUP(F34,'Risk Chart'!$B$22:$C$26,2),IF(E34 = "Low", VLOOKUP(F34,'Risk Chart'!$B$7:$C$11,2),IF(E34 = "Medium", VLOOKUP(F34,'Risk Chart'!$B$12:$C$16,2), "")))))
G35: =IF(E35 = "High", VLOOKUP(F35,'Risk Chart'!$B$2:$C$6,2),IF(E35 = "Very High", VLOOKUP(F35,'Risk Chart'!$B$17:$C$21,2),IF(E35 = "Very Low", VLOOKUP(F35,'Risk Chart'!$B$22:$C$26,2),IF(E35 = "Low", VLOOKUP(F35,'Risk Chart'!$B$7:$C$11,2),IF(E35 = "Medium", VLOOKUP(F35,'Risk Chart'!$B$12:$C$16,2), "")))))
G36: =IF(E36 = "High", VLOOKUP(F36,'Risk Chart'!$B$2:$C$6,2),IF(E36 = "Very High", VLOOKUP(F36,'Risk Chart'!$B$17:$C$21,2),IF(E36 = "Very Low", VLOOKUP(F36,'Risk Chart'!$B$22:$C$26,2),IF(E36 = "Low", VLOOKUP(F36,'Risk Chart'!$B$7:$C$11,2),IF(E36 = "Medium", VLOOKUP(F36,'Risk Chart'!$B$12:$C$16,2), "")))))
G37: =IF(E37 = "High", VLOOKUP(F37,'Risk Chart'!$B$2:$C$6,2),IF(E37 = "Very High", VLOOKUP(F37,'Risk Chart'!$B$17:$C$21,2),IF(E37 = "Very Low", VLOOKUP(F37,'Risk Chart'!$B$22:$C$26,2),IF(E37 = "Low", VLOOKUP(F37,'Risk Chart'!$B$7:$C$11,2),IF(E37 = "Medium", VLOOKUP(F37,'Risk Chart'!$B$12:$C$16,2), "")))))
G38: =IF(E38 = "High", VLOOKUP(F38,'Risk Chart'!$B$2:$C$6,2),IF(E38 = "Very High", VLOOKUP(F38,'Risk Chart'!$B$17:$C$21,2),IF(E38 = "Very Low", VLOOKUP(F38,'Risk Chart'!$B$22:$C$26,2),IF(E38 = "Low", VLOOKUP(F38,'Risk Chart'!$B$7:$C$11,2),IF(E38 = "Medium", VLOOKUP(F38,'Risk Chart'!$B$12:$C$16,2), "")))))
G39: =IF(E39 = "High", VLOOKUP(F39,'Risk Chart'!$B$2:$C$6,2),IF(E39 = "Very High", VLOOKUP(F39,'Risk Chart'!$B$17:$C$21,2),IF(E39 = "Very Low", VLOOKUP(F39,'Risk Chart'!$B$22:$C$26,2),IF(E39 = "Low", VLOOKUP(F39,'Risk Chart'!$B$7:$C$11,2),IF(E39 = "Medium", VLOOKUP(F39,'Risk Chart'!$B$12:$C$16,2), "")))))
G40: =IF(E40 = "High", VLOOKUP(F40,'Risk Chart'!$B$2:$C$6,2),IF(E40 = "Very High", VLOOKUP(F40,'Risk Chart'!$B$17:$C$21,2),IF(E40 = "Very Low", VLOOKUP(F40,'Risk Chart'!$B$22:$C$26,2),IF(E40 = "Low", VLOOKUP(F40,'Risk Chart'!$B$7:$C$11,2),IF(E40 = "Medium", VLOOKUP(F40,'Risk Chart'!$B$12:$C$16,2), "")))))
...

Sheet Action Items
A1: Action Items
A2: Sr. No | B2: Description | C2: Owner | D2: Date Raised | E2: Due Date | F2: Date Completed | G2: Status | H2: Comments
A3: =ROW()-2 -> 1 | B3: Prepare New Data distribution package estimates | C3: Lead | D3: 44849 | E3: 44852 | F3: 44852 | G3: Closed | H3: Data Distribution
A4: =IF(B3="","",A3+1) -> 2 | B4: Prepare estimates for remaining work on HMS | C4: Lead | D4: 44852 | E4: 44852 | F4: 44852 | G4: Closed | H4: HMS - (4 + 2 days)
A5: =IF(B4="","",A4+1) -> 3 | B5: Estimates required to upgrade Carbon UI to Living Design | C5: QA Lead | D5: 44852 | E5: 44852 | F5: 44852 | G5: Closed | H5: Cost Reorder (3 days)
A6: =IF(B5="","",A5+1) -> 4 | B6: saqib to update project plan as discused on SOS | C6: PM 1
A7: =IF(B6="","",A6+1) -> 5 | B7: Estimates required to fix OutOfMemory Issue in MDDB Load Batch Job | C7: PM 1 | D7: 44853 | E7: 44854 | F7: 44854 | G7: Closed | H7: MDDB Load Batch Job - optimization dev work planned to be finalized by 26th Oct
A8: =IF(B7="","",A7+1) -> 6 | B8: Progress Last Week ​ Dev : Advance search queries discovery 50%​ Dev : Work Order API 90%​ Dev : Work Order Scheduling for pill images 30% ​ QA : Pill Image test case writing 60%​ Next week - In Progress​ Dev : Basic/advance search queries discovery ​ Dev : Work Order ​ QA : Pill Images test case writing | C8: PM 1 | D8: 44853 | E8: 44854 | F8: 44854 | G8: Closed
A9: =IF(B8="","",A8+1) -> 7 | B9: Progress Last Week ​ Dev : Save new item with new product 70%​ UI : Add/Edit Product 70%​ Next week - In Progress​ Dev : Save new item with new product 100%​ UI : Add/Edit product 100%​ QA : Test case execution add/edit ​ Key Notes | C9: PM 1 | D9: 44853 | E9: 44854 | F9: 44854 | G9: Closed
A10: =IF(B9="","",A9+1) -> 8 | B10: Progress Last Week ​ Dev : Work Order Scheduling 30% ​ UI : Mass Item Update 50%​ UI : Group Item Update 30%​ Next week - In Progress​ Demo : Complete flow Search/Add/Edit​ Dev : Work Order Scheduling 50%​ UI : Mass Item Update 70%​ UI : Group Item Update 50% | C10: PM 1 | D10: 44853 | E10: 44854 | F10: 44854 | G10: Closed
A11: =IF(B10="","",A10+1) -> 9 | B11: Project Handover Documentation Closure | C11: PM 2 | D11: 45140 | E11: 45183 | G11: Closed | H11: Document was created earlier. just need to sign off on items
A12: 10 | B12: Ayyaz travel plan | C12: PM 2 | D12: 45175 | E12: 45199 | G12: Closed | H12: Need to Schedule the meeting with Fahid Sb with in this week.
A13: 11 | B13: High Low Performance List | C13: PM 2 | D13: 45174 | E13: 45174 | F13: 45174 | G13: Closed
A14: 12 | B14: Amir's involvement as architect | C14: PM 2 | D14: 45174 | E14: 45182 | G14: Closed | H14: Need to Schedule the meeting Regular catch up with Amir Document specify things.
A15: 13 | B15: Low performers fortnightly followup meeting | C15: PM 2 | D15: 45174 | E15: 45174 | F15: 45174 | G15: Closed | H15: Meetings Scheduled with Hassan Amjad and Hassan Ahmed Hassan Ahmed Minhas should start coming to office
A16: 14 | B16: Assign mentors to high performers | C16: PM 2 | D16: 45174 | G16: Open | H16: 04 Oct: We will initiate a discussion on this with PEC Focused group
A17: 15 | B17: New Line Management Structure | C17: PM 2 | D17: 45252 | E17: 45270 | F17: 45270 | G17: Closed | H17: TLs have been assinged LM roles.
A18: =IF(B17="","",A17+1) -> 16 | B18: New Team Structure Post Production | C18: PM 2 | D18: 45281 | E18: 44941 | F18: 44941 | G18: Closed | H18: Support team for whole carbon drug - Kanabn Development team for Post MVP - New Feature
A19: =IF(B18="","",A18+1) -> 17 | B19: Support cycle | C19: PM 2 | D19: 45281 | E19: 44941 | F19: 44941 | G19: Closed | H19: A common confluce page has been setup with the information
A20: =IF(B19="","",A19+1) -> 18 | B20: SLA | C20: PM 2 | D20: 45281 | E20: 44941 | F20: 44941 | G20: Closed | H20: A common confluce page has been setup with the information
A21: 19 | B21: RCA pages | C21: PM 2 | D21: 45281 | E21: 44941 | F21: 44941 | G21: Closed | H21: A common confluce page has been setup with the information
A22: 20 | B22: Hypercare plan | C22: PM 2 | D22: 45281 | E22: 44941 | G22: Closed | H22: Slack Channel support team timing work hours on call support -
A23: =IF(B22="","",A22+1) -> 21 | B23: Need Support from Fahid Sb on Support Team ways of working 1) How to provide hardship allowance 2) KPI for support (Number of issues/Cycle time/Type of issue) 3) Extended Timings of members on support 4) Any existing model ? | C23: PM 2 | D23: 45307 | E23: 45322 | G23: Open | H23: PM to setup call with Fahid and PM for hardship allowance
A24: =IF(B23="","",A23+1) -> 22 | B24: Goals Creation of teams | C24: Leads | D24: 45322 | E24: 45322 | G24: Closed
A25: =IF(B24="","",A24+1) -> 23 | B25: Need clarity from the customer about the SoW approval for the new thread/work | C25: PM 1 | D25: 45322 | E25: 45322 | G25: Open
A26: =IF(B25="","",A25+1) -> 24 | B26: Confirmation of the support plan completion timelines with PM | C26: PM 2 | D26: 45322 | E26: 45322 | G26: Open | H26: March/APril end continuation
A27: =IF(B26="","",A26+1) -> 25 | B27: Team leaves carry forward for year 2023. Discussion and approval was already received from the management | C27: PM 2 | D27: 45322 | E27: 45322 | G27: Open | H27: Leaves of 2023 are not incorporated in leaves quota for 2024 for the team
A28: =IF(B27="","",A27+1) -> 26 | B28: Few members of development team are engaged to explore the remaining modules of legacy system - Insurance, central fill, immunization, store | C28: Lead 1 | D28: 45322 | E28: 45322 | G28: Open
A29: =IF(B28="","",A28+1) -> 27 | B29: Get clarity about the Soft launch starting plan | C29: Lead 2 | D29: 45322 | E29: 45322 | G29: Closed | H29: Started on 5th Feb
A30: =IF(B29="","",A29+1) -> 28 | B30: Update line management of leads to PM | C30: PM | D30: 45322 | E30: 45329 | G30: Open | H30: Amir goals setup and line management updates are still pending. Nauman shared this with Hussain

Sheet Assumptions
A1: Assumptions
A2: Sr. No | B2: Description | C2: Source | D2: Criticality | E2: Next Steps | F2: Owner | G2: Date Raised | H2: Validation Due | I2: Date Validated | J2: Validated | K2: Comments
A3: =ROW()-2 -> 1 | B3: Soft launch will start from 1st of February and will be completed by 7th of Feb | C3: Team discussion and plan for production go live | D3: Low | E3: Get clarity from the business about the exact date Establish a communication plan for gathering feedback from users during the soft launch. Schedule a post-soft launch review meeting to discuss feedback and identify any necessary adjustments. | F3: Lead | G3: 45322 | I3: 45327 | J3: Yes
A4: 2 | B4: Business users on-boarding on 8 and 9th Feb | C4: Team discussion and plan for production go live | D4: Medium | E4: Collect feedback from business users regarding their onboarding experience. Conduct a review meeting to address any issues identified during onboarding and refine processes if necessary. | F4: Leads | G4: 45322 | I4: 45330 | J4: Yes
A5: =IF(B3="","",A4+1) -> 3 | B5: Shut down the legacy system and jobs over the weekend | C5: Team discussion and plan for production go live | D5: Medium | E5: Develop a detailed plan for the shutdown, ensuring all critical data is migrated or backed up. Communicate the shutdown plan to all relevant stakeholders, including users and support teams. Prepare contingency plans for any unforeseen issues during the shutdown. | F5: Leads | G5: 45322 | I5: 45332 | J5: Yes
A6: 4 | B6: Supporting activities will start from 12th of February | C6: Team discussion and plan for production go live | D6: Medium | E6: Establish communication channels for users to report issues and seek assistance. Schedule regular check-ins with support teams to address any emerging challenges. | F6: Leads | G6: 45322 | I6: 45327 | J6: Yes
A7: =IF(B6="","",A6+1) -> 5 | B7: Supporting activities will be completing in the first week of March and Support team members will be available for the development work on the new thread | C7: Team discussion and plan for production go live | D7: Medium | E7: Conduct a thorough review of all supporting activities to ensure completion. Document lessons learned and areas for improvement in support processes. Communicate the completion of supporting activities to relevant stakeholders. | F7: Leads | G7: 45322 | H7: 45350 | K7: 27-Feb: PM mentioend that Support will be part of new SoW as well so it will be continue for till March/April end
A8: 6 | B8: Development team is doing RnD on the new module Central Fill with the assumption that SoW will be approved in the month of March. Need clarity about the new SoW | C8: Saqib mention this couple of times during discussion | D8: Medium | E8: Development team to conclude the PRD review for the available informnation and document the details on confluence | F8: Leads | G8: 45343
A9: =IF(B8="","",A8+1) -> 7
A12: =IF(B11="","",A11+1)
A13: =IF(B12="","",A12+1)
A14: =IF(B13="","",A13+1)
A15: =IF(B14="","",A14+1)
A16: =IF(B15="","",A15+1)
A17: =IF(B16="","",A16+1)
A18: =IF(B17="","",A17+1)
A19: =IF(B18="","",A18+1)
A20: =IF(B19="","",A19+1)
A21: =IF(B20="","",A20+1)
A22: =IF(B21="","",A21+1)
... A39: =IF(B38="","",A38+1)

Sheet Milestones
A1: Milestones
A2: Sr. No | B2: Description | C2: Environment | D2: Phase | E2: Due Date | F2: At Risk? | G2: Achieved Date | H2: Status | I2: Comments
A3: =ROW()-2 -> 1 | B3: UAT of Prescriber - session 1 | C3: Staging | D3: <Phase 1> | E3: 23/1/2022 | F3: No | H3: Achieved
A4: =ROW()-2 -> 2 | B4: UAT of Prescriber - session 2 | C4: Staging | D4: <Phase 1> | E4: 44622 | F4: No | H4: Achieved
A5: =ROW()-2 -> 3 | B5: Cost and Reorder UAT - session 1 | C5: Staging | D5: <Phase 1> | E5: 44650 | F5: No | H5: Achieved
A6: =ROW()-2 -> 4 | B6: Data Distribution | C6: Staging | D6: <Phase 1> | E6: 45107 | F6: No | H6: Achieved
A7: =IF(B6="","",A6+1) -> 5 | B7: Prescriber | C7: Production | D7: <Phase 2> | E7: 45101 | F7: No | G7: 45101 | H7: Achieved | I7: V&V in progress - new bugs identified
A8: =IF(B7="","",A7+1) -> 6 | B8: Data Distribution packages ​ (Pill Image, GPI State Exception, BU license, Urgent Message) | C8: Staging | D8: <Phase 1> | E8: 45078 | F8: No | G8: 45078 | H8: Achieved | I8: QE Sign off done 25 Oct- 08 Nov: Pilot Stores (1-9) Deployment In Progress
A9: 7 | B9: Medguide (Tools) | C9: Development | D9: <Phase 2> | E9: 45204 | F9: No | G9: 45224 | H9: Achieved | I9: UAT Sign Off 08 - Nov Production Deployment In progress
A10: =ROW()-2 -> 8 | B10: NDC (Tools) | C10: Development | D10: <Phase 2> | E10: 45190 | F10: No | G10: 45224 | H10: Achieved | I10: UAT Planned
A11: =ROW()-2 -> 9 | B11: Drug History (Tools) | C11: Development | D11: <Phase 2> | E11: 45214 | F11: No | G11: 45224 | H11: Achieved | I11: UAT Planned
A12: 9 | B12: Cost and Reorder with New Req | C12: Staging | D12: <Phase 2> | E12: 45218 | F12: No | H12: Planned | I12: 19 Oct:UAT Planned 16 Nov: UAT completed but bug fixes/new req in progress
A13: =IF(B12="","",A12+1) -> 10 | B13: Item/Product/MDDB | C13: Development | D13: <Phase 2> | E13: 45238 | F13: No | G13: 45212 | H13: Achieved | I13: Few minor bugs in fix.. will merge Node 18 changes on Sat 25 04 Oct: On track to get sign off on 06 Oct 03 Nov: UAT and Fixes InProgress
A14: =IF(B13="","",A13+1) -> 11 | B14: Item/Product/MDDB | C14: Staging | D14: <Phase 2> | E14: 45256 | F14: No | H14: Planned | I14: 08 Nov: Production Deployment InProgress but was reverted due to Node 18 was not supported 17 Nov: UAT Signoff Pending - 28 Nov Carbon UI Nov
A15: =IF(B13="","",A13+1) -> 11 | B15: GPI | C15: Development | D15: <Phase 2> | E15: 45190 | F15: No | G15: 45205 | H15: Achieved | I15: Time line extended due to QA Cycle delay
A16: =IF(B15="","",A15+1) -> 12 | B16: GPI | C16: Staging | D16: <Phase 2> | E16: 45230 | F16: No | G16: 45230 | H16: Achieved | I16: 31 Oct: UAT Completed
A17: =IF(B15="","",A15+1) -> 12 | B17: OIF | C17: Development | D17: <Phase 2> | E17: 45226 | F17: No | G17: 45243 | H17: Achieved | I17: UAT Planned
A18: =IF(B17="","",A17+1) -> 13 | B18: OIF | C18: Staging | D18: <Phase 2> | E18: 45246 | F18: No | G18: 45274 | H18: Achieved | I18: 14 Dec: UAT Done
A19: =IF(B17="","",A17+1) -> 13 | B19: Data Distribution​ (BU License Package) | C19: Staging | D19: <Phase 2> | E19: 45184 | F19: No | G19: 45191 | H19: Achieved | I19: July 21st Signoff handover – UAT InProgress - ETA – 4 weeks 04 Oct: for GPI Changes we will get sign off on 06 Oct
A20: =IF(B19="","",A19+1) -> 14 | B20: Pill Image | C20: Staging | D20: <Phase 1> | E20: 45110 | F20: No | G20: 45141 | H20: Achieved | I20: UAT Achieved
A21: =IF(B20="","",A20+1) -> 15 | B21: ClarusOne (part of C&R) | C21: Development | D21: <Phase 2> | E21: 45233 | F21: Yes | H21: Planned | I21: API integration still pending on ClarusOne third party 16 Nov: It was at Risk but now it is being planned and new date is not yet determined. Hence it is not at Risk against any date as of yet. 13 Dec: This is back AT Risk
A22: 16 | B22: Data Distribution​ Read API + Consumer App | C22: Production | D22: <Phase 2> | E22: 45268 | F22: No | G22: 45264 | H22: Achieved | I22: 01 Dec - 04 Dec: Resumed the store side package deployments after Thanksgiving break Deployed to all 5000+ stores
A23: 17 | B23: Package Tracking Dashboard | C23: Staging | D23: <Phase 2> | E23: 45267 | F23: No | H23: Planned | I23: 11 Dec: UAT Planned for today.
A24: =IF(B23="","",A23+1) -> 18 | B24: Production Store Side Deployments | C24: Production | D24: <Phase 2> | E24: 45313 | F24: No | H24: Planned | I24: 01 Jan: Production Deployments starting from - 08 Jan 2024
A25: =IF(B24="","",A24+1) -> 19 | B25: Production Carbon UI + Jobs Deployments | C25: Production | D25: <Phase 2> | E25: 45313 | F25: No | H25: Planned | I25: 01 Jan: Production Deployments starting from - 12 Jan 2024
A26: =IF(B25="","",A25+1) -> 20 | B26: Initiate Soft Launch Activities | C26: Production | D26: <Phase 2> | E26: 45292 | F26: No | G26: 45327 | H26: Achieved | I26: Soft Launch Activities started on 5th Feb
A27: =IF(B26="","",A26+1) -> 21 | B27: Onboarding Business User for Soft launch | C27: Production | D27: <Phase 2> | E27: 45299 | F27: No | H27: Achieved | I27: Business users on-boarding on 8 and 9th Feb
A28: =IF(B27="","",A27+1) -> 22 | B28: Shut down the legacy system and jobs over the weekend | C28: Production | D28: <Phase 2> | E28: 45301 | F28: No | H28: Achieved | I28: Shut down the legacy system and jobs over the weekend i.e. 10 and 11 Feb
A29: =IF(B28="","",A28+1) -> 23 | B29: Supporting activities will start from 12th of February | C29: Production | D29: <Phase 2> | E29: 45303 | F29: No | H29: Achieved
A30: =IF(B29="","",A29+1) -> 24 | B30: Production Roll out planning for the issues | C30: Production | D30: <Phase 2> | E30: 45343 | F30: No | H30: Planned | I30: Planning a release to resolve the open issues in this week and next week
A32: =IF(B31="","",A31+1)
A33: =IF(B32="","",A32+1)
A34: =IF(B33="","",A33+1)
A35: =IF(B34="","",A34+1)
A36: =IF(B35="","",A35+1)
A37: =IF(B36="","",A36+1)
A38: =IF(B37="","",A37+1)

Sheet Issues
A1: Issues
A2: Sr. No | B2: Description | C2: Impact | D2: Priority | E2: Root Cause Analysis | F2: Resolution | G2: Owner | H2: Date Raised | I2: Date Due | J2: Date Resolved | K2: Status | L2: Comments
A3: 1 | B3: SOW Renewal and VDI expiry | C3: Team members will not be able to access the vdi and cannot continue work | D3: High | E3: Contract Expiry | F3: Contract Renewal | G3: Adam | H3: 23-05-23 | J3: 30-06-2023 | K3: Closed | L3: It is renewed
A4: =IF(B3="","",A3+1) -> 2 | B4: Sadia has resigned - May 08, 2023 Last day is June 27. | C4: We will have to work with reduced capacity until we can get the replacement from bench | D4: Medium | E4: Resigned | F4: We have got a QA replacement | G4: Ayyaz | H4: 23-05-23 | J4: 45083 | K4: Closed | L4: Action Taken: KT sessions completed Access Revoked- from Confiz & Walmart
A5: =IF(B4="","",A4+1) -> 3 | B5: QA resources need a mentor to guide them for the Advanced QA processes without proper mentorship their perfomance will be limited | C5: We missed lots of test scenarios for Prescriber. It impacted the Quality of our deliverable. | D5: Medium | E5: We do not have Test Architect in RDM MO Team | F5: Atieq & QA team agreed that we can learn from our mistakes from Prescriber and will start cross training the team | G5: Ayyaz/Atieq | H5: 14-06-2023 | K5: Closed
A6: =IF(B5="","",A5+1) -> 4 | B6: Manual Testing takes a lot of time for us to perform testing plus in time critical situations it hampers our ability to respond and deploy in a timely manner | C6: Time to react/Huge time is lost by manual testing | D6: Medium | E6: Lack of QA Automation/ Lack of experienced trained QA Talent | F6: Initiated Cypress Automation task by utilizing Israr expertise Directed other team members to start getting training on Cypress Automation Assigning Cypress training as a goal for QA team members | G6: Ayyaz/Atieq | H6: 45083 | K6: Closed | L6: Action Taken: Team has been given a task to determin the current state of Automation and provide estimates of implementing E2E automation for entire project
A7: =IF(B6="","",A6+1) -> 5 | B7: We need UI Lead to take ownership of UI related Issues | C7: We end up discussing most of the UI techincal Issues with Junior team members. or have to step into the situation/meetings ourselves | D7: High | E7: Hassan Amjad has availablity issues + at times he is not taking full ownership of UI related issues | F7: Planning to send an official email after my 1-1 to discuss these concerns with Hassan Amjad | G7: Ayyaz | H7: 45083 | J7: 45114 | K7: Closed | L7: Planned a 1-1 with Hassan Today but it had to be rescheduled as he was not available
A8: =IF(B7="","",A7+1) -> 6 | B8: Requirements are not directly understood by QA - Dev lead the requirements | C8: Gap in requirement understanding impacts the overall quality of the product | D8: High | E8: Scrum team was never made part of origional requirement gathering +QA were always led by Scrum Masters for requirement understanding | F8: QAs are now leading the requirement gathering and grooming session and updating the confluence pages accordingly | G8: Ayyaz | H8: 45083 | K8: Closed | L8: Action Taken: Recently made QA team members responsible for actively participating in Requirement gathering meetings/grooming meetings Now QAs are responsible for taking Minutes of the meetings and to update the requirements in confluence.
A9: =IF(B8="","",A8+1) -> 7 | B9: Salary concerns raised by 3 of our key team members | C9: They could start looking opportunities outside Confiz. In this way we will loose our experienced and good performing Team Leads which will definitly impact our Project success | D9: High | E9: Their salaries are lower than the current Market rate as per their experience and designation | F9: We need to carefully review their salaries before July's increment | G9: Fahid | H9: 18/07/2023 | K9: Closed | L9: Action taken: Had requested the resources to have 1-1 with Fahid Sb on this.
A10: 8 | B10: Test Engineer Mustafa Shabaz has resigned | C10: Quality of the Project: We are already QA Deficient and lots of threads are in progress hence QA will become bottle neck | D10: High | E10: Mustafa has future plans to move to US and his career moves are in line with his future plans | F10: We need another QA to replace Mustafa in RDM MO | G10: Fahid | H10: 45134 | K10: Closed | L10: Action Taken: Had internal meeting with Team Leads to evaluate resource requirement and team agreed we need QA resource to replace Mustafa ASAP. I have informed PL accordingly.
A11: =IF(B10="","",A10+1) -> 9 | B11: Hassan Amjad Performance & availability issues | C11: Quality and Timeliness of the Project Drug Modules Item, Product, MDDB, Mass Update/ GPI OIF | D11: High | E11: As per Hassan he has family issues Mother + Kid | F11: 1) Provide official feed back on tickets 2) Monitor performance more closely 3) if situation persists for September will need to request for replacement | G11: Ayyaz | H11: 45160 | I11: 45290 | K11: Closed | L11: Action Taken: 1) Have had discussed the feedback with him earlier as well 2) Today again shared the feedback on 22 Aug 3) Made him aware that I will be reporting the summary of feedback on his goal ticket 4) Made him aware that if he still coudnlt manage to improve the situation we might ask for his replacement (depending on the situation might also intiate Elevate Plan)
A12: =IF(B11="","",A11+1) -> 10 | B12: Hassan Ahmed Minhas Performance Issues | C12: Quality and Timeliness of the Project Specific impact: On the quality of Tools Module: Medguide/NDC Linking/Drug History/etc General Impact: He is the senior most resource in QA hence it can impact overall QA team/Over all quality of the Project | D12: High | E12: He is going through personal life/family pressures due to loss of his both Parents. He has a younger brother who has special needs. His Sister is getting married in Sept. | F12: 1) Provide official feed back on tickets 2) Monitor performance more closely 3) if situation persists for September will need to request for replacement | G12: Ayyaz | H12: 45160 | I12: 45290 | K12: Closed | L12: Action Taken: 1) Have had discussed the feedback with him earlier as well 2) Today again shared the feedback on 22 Aug 3) Made him aware that I will be reporting the summary of feedback on his goal ticket 4) Made him aware that if he still coudnlt manage to improve the situation we might ask for his replacement (depending on the situation might also intiate Elevate Plan)
A13: 11 | B13: [Change Request] - User should be able to send package without making any change (WO) | C13: Scope changes will impact Production Timelines | D13: High | E13: Missing Requirements were never brought up by WM | F13: - UI Mockup Required. - Business understanding required. | G13: Amir | H13: 45233 | I13: 44901 | K13: Closed | L13: work in progress 01 Dec: Demo given to clients
A14: =IF(B13="","",A13+1) -> 12 | B14: [Change Request] - Package can be delivered to selected stores | C14: Scope changes will impact Production Timelines | D14: High | E14: Missing Requirements were never brought up by WM | F14: - UI Mockup Required. - Business understanding required. - Need to look into how to handle the Store distribution list. | G14: Amir | H14: 45233 | I14: 44901 | K14: Closed | L14: work in progress 01 Dec: Demo given to clients
A15: =IF(B14="","",A14+1) -> 13 | B15: [Change Request] - Package / CnR Report should not be send in business hours | C15: Scope changes will impact Production Timelines | D15: High | E15: Missing Requirements were never brought up by WM | F15: - Need agreement with business on scope and functionality - Understanding Required on Package Scheduling | G15: Amir/Adil | H15: 45233 | I15: 44907 | K15: Closed | L15: work in progress 01 Dec: Dev Completed
A16: =IF(B15="","",A15+1) -> 14 | B16: [Change Request] - New Store Drug Load | C16: Scope changes will impact Production Timelines | D16: High | E16: Missing Requirements were never brought up by WM | F16: - UI Mockups required - Agreement with business on scope and functionality | G16: Amir | H16: 45233 | K16: Closed | L16: Post MVP (Feb onwards - Due date yet to be determined)
A17: =IF(B16="","",A16+1) -> 15 | B17: [Change Request] - Package Tracking | C17: Scope changes will impact Production Timelines | D17: High | E17: Missing Requirements were never brought up by WM | F17: - UI Mockup required - Agreement with business regarding scope and functionality | G17: Amir/Komal | H17: 45233 | I17: 44901 | K17: Closed | L17: work in progress 01 Dec: Demo giving to clients 13 Dec: UAT on 15 Dec -On Track
A18: 16 | B18: [Change Request] - Drug Read APIs need new service for CCM2 Migration | C18: Scope changes will impact Production Timelines | D18: High | E18: CCM2 Migration is done by WM but they are facing issues in Production | F18: Implementation of new service | G18: Komal/Ramzan | H18: 45231 | I18: 44895 | K18: Closed | L18: These are the shared repositories and hence WM team was having the ownership for these kind of changes but during the Production deployment WM team faced issues with CCM2 and shifted the ownership to RDM MO team 13 Dec: On Track
A19: =IF(B18="","",A18+1) -> 17 | B19: [Missed Communication from WM] - Cost & Reorder Batch Job Query changed by WM RDM Team | C19: We need to get it registered by IQS during their freeze period on special permission via Shaun | D19: High | E19: WM made some changes in the code which they forgot to inform us. | F19: Get it registered by IQS | G19: Adil/Ramzan | H19: 45233 | I19: 44907 | K19: Closed | L19: In discussion with IQS - they have routed us to one of their GCP team to get our end points onboarded 01 Dec: Team working to create queries for GCP Team 13 Dec: We have made a good progress data is flowing through GCP we are now in process of verifying the data itself.
A20: =IF(B19="","",A19+1) -> 18 | B20: [Missed Dependency from WM ] - HW Data in TeraData Tables - Informix Database - Legacy Feed | C20: We cannot swtich to new deployment untill and unless this feed data is migrated to new cloud DB | D20: High | E20: WM team missed to identify this dependency in the initial phases | F20: Data Migration Plan to be confirmed by WM | G20: WM | H20: 45233 | I20: 44925 | K20: Open | L20: 01 Dec: work in progress from WM 13 Dec: workin Progress from WM and they have confirmed they are on Track
A21: =IF(B20="","",A20+1) -> 19 | B21: [Change Request] - Change Item cost in Same day | C21: Requirement Change implementation will impact Production Timelines - Carbon UI - BE API - Drug history / CnR " | D21: High | E21: New Requirement | F21: Requirements pending. | G21: Adil/Ramzan | H21: 45233 | I21: 44907 | K21: Closed | L21: Proposed the solution to the business now waiting on their response 01 Dec: Development In Progress 13 Dec: On Track
A22: =IF(B21="","",A21+1) -> 20 | B22: GPI Template | C22: New Development to find its trigger point - MDDB to Patient Safty data | D22: High | E22: New Requirement | F22: Create email and send it | G22: Ramzan | H22: 45240 | I22: 45272 | K22: Closed | L22: Changes suggested in GPI Email template - Analysis in progress few questions pending on clients 01 Dec: Changes presented to Clients waiting for approval 13 Dec: On Track
A23: =IF(B22="","",A22+1) -> 21 | B23: SOX Compliance | C23: Migrate from KeyVault to AKeyLess Minor impact on integration | D23: High | E23: New Requirement | F23: Integration to AKeyLess Server | G23: Amir | H23: 45240 | I23: 45272 | K23: Closed | L23: SOX Compliance - Migration to AkeyLess (KeyVault passwords API/DB) 01 Dec: Coordinating with Sindhoor to get NameSpaces etc. 13 Dec: On Track
A24: =IF(B23="","",A23+1) -> 22 | B24: For Production Release we need to disable legacy application menus/services | C24: We are not contractually obliged to change Legacy GPH app if something goes wrong we will have to take the blame | D24: High | E24: We should take a firm stance in these kind of situations | G24: Ayyaz | H24: 45308 | I24: 45322 | K24: Closed | L24: Agreed Decision - FE service will be shut down by the Walmart team and BE services will be shut down by Confiz team
A25: =IF(B24="","",A24+1) -> 23
A26: =IF(B25="","",A25+1)
A27: =IF(B26="","",A26+1)
A28: =IF(B27="","",A27+1)
A29: =IF(B28="","",A28+1)
A30: =IF(B29="","",A29+1)
A31: =IF(B30="","",A30+1)
A32: =IF(B31="","",A31+1)
A33: =IF(B32="","",A32+1)
A34: =IF(B33="","",A33+1)
A35: =IF(B34="","",A34+1)
A36: =IF(B35="","",A35+1)
... A40: =IF(B39="","",A39+1)

Sheet Decisions
A1: Decisions
A2: Sr. No | B2: Description | C2: Rationale | D2: Decided By | E2: Date Decided | F2: Comments
A3: 1 | B3: We will replace Mustafa S (Test Engineer) with another Test Engineering resource | C3: we are QA deficient and have enough FE resources already. | D3: PM 2 | E3: 45147
A4: =IF(B3="","",A3+1) -> 2 | B4: We will be hiring new QA resource externally (from the Market) | C4: we do not have QA resource available within Confiz | D4: PM 2 | E4: 45154 | F4: Faizan sid will be available from 18 Sept onwards Soft Test Engineer
A5: =IF(B4="","",A4+1) -> 3 | B5: Hassan Ahmed Minhas is swapped with Israr Javed (Tools / GPI) | C5: Tools has a complex domain and team lead was not satisfied with Hassan's Performance. (GPI/OIF is relatively straightforward) | D5: PM 2 | E5: 45173
A6: 4 | B6: New Dev Salahudin enagaged with Tools Team | C6: Tools team has the most complex work that includes FE development so its a good learning ground | D6: PM 2 | E6: 45184
A7: =IF(B6="","",A6+1) -> 5 | B7: New TE Faizan Siddique Engagaed with Tools Team to replace Mustafa | C7: Mustafa resigned and he was working for Tools Team | D7: PM 2 | E7: 45184
A8: 6 | B8: Packages Apply - Manually updates the status of package in Database and this has already been shared with the customer | C8: To show correct information/data on the status dashboard | D8: PM 1 | E8: 44957
A9: 7 | B9: Ops team on-boarding package - Daily monitor the store consumer application and restart if required and this has been shared with customer | C9: To apply the packages on all stores | D9: PM 1 | E9: 44957
A10: =IF(B9="","",A9+1) -> 8
A11: =IF(B10="","",A10+1)
A12: =IF(B11="","",A11+1)
A13: =IF(B12="","",A12+1)
A14: =IF(B13="","",A13+1)
A15: =IF(B14="","",A14+1)
A16: =IF(B15="","",A15+1)
A17: =IF(B16="","",A16+1)
A18: =IF(B17="","",A17+1)
A19: =IF(B18="","",A18+1)
A20: =IF(B19="","",A19+1)
A21: =IF(B20="","",A20+1)
... A25: =IF(B24="","",A24+1)

Sheet Dependencies
A1: Dependencies
A2: Sr. No | B2: Description | C2: Importance | D2: Owner | E2: Date Raised | F2: Due Date | G2: Date Completed | H2: Status | I2: Comments
A3: 1 | B3: For GPI we have dependency on IQS team which a Third Party company to provide access to their Stage environments | C3: Very High | D3: Ramzan | E3: 45078 | G3: 45147 | H3: Closed
A4: =IF(B3="","",A3+1) -> 2 | B4: Connexus not working on test boxes. | C4: Very High | D4: Amir | E4: 45170 | F4: 45204 | G4: 45214 | H4: Closed
A5: =IF(B4="","",A4+1) -> 3 | B5: IQS onboarding for OIF | C5: Very High | D5: Ramzan | E5: 45139 | F5: 45184 | G5: 45200 | H5: Closed
A6: 4 | B6: ClarusOne API access | C6: Very High | D6: Saqib | E6: 45139 | F6: 45191 | G6: 45261 | H6: Closed
A7: 5 | B7: IQS onboarding for Cost & Reorder | C7: Very High | D7: Adil | E7: 45231 | F7: 45260 | G7: 45261 | H7: Closed
A9: =IF(B8="","",A8+1)
A10: =IF(B9="","",A9+1)
A11: =IF(B10="","",A10+1)
A13: =IF(B12="","",A12+1)
A14: =IF(B13="","",A13+1)
A15: =IF(B14="","",A14+1)
A16: =IF(B15="","",A15+1)
A17: =IF(B16="","",A16+1)
A18: =IF(B17="","",A17+1)
A19: =IF(B18="","",A18+1)
A20: =IF(B19="","",A19+1)
A21: =IF(B20="","",A20+1)
... A41: =IF(B40="","",A40+1)

Sheet KPI
A1: <Project Name>
A2: Project Type | B2: Managed Outcome
B3: KPI | C3: Applicability | D3: Frequency | E3: Possible Values | F3: Target Value | G3: Owner | H3: 44927 | I3: 44958 | J3: 44986 | K3: 45017 | L3: 45047 | M3: 45078 | N3: 45108 | O3: 45139 | P3: 45170 | Q3: 45200 | R3: 45231 | S3: 45261 | T3: 45292 | U3: 45323 | V3: 45352 | W3: 45383 | X3: 45413 | Y3: 45444 | Z3: 45474
A4: Excellence in Delivery | B4: Were all (if any) estimates shared after proper requirements analysis? | C4: Y | D4: Monthly | E4: YES | NO | F4: YES | G4: US Delivery Lead | H4: Yes | I4: Yes | J4: Yes | K4: Yes | L4: Yes | M4: Yes | N4: Yes | O4: Yes | P4: Yes | Q4: Yes | R4: Yes | S4: Yes | T4: Yes | U4: Yes
B5: Number of tasks committed without proper acceptance criteria? | C5: Y | D5: Monthly | E5: Number >= 0 | F5: 0 | G5: US Delivery Lead | L5: 0 | M5: 0 | N5: 0 | O5: 0 | P5: 0 | Q5: 0 | R5: 0 | S5: 0 | T5: 0 | U5: 0
B6: Missed delivery deadlines? | C6: Y | D6: Monthly | E6: YES | NO | F6: NO | G6: US Delivery Lead | H6: No | I6: No | J6: No | K6: No | L6: Yes | M6: No | N6: No | O6: No | P6: No | Q6: No | R6: No | S6: No | T6: No | U6: No
B7: Does an identified product backlog exist from where sprint backlog is populated? | C7: Y | D7: Monthly | E7: YES | NO | F7: YES | G7: US Delivery Lead | H7: Yes | I7: Yes | J7: Yes | K7: Yes | L7: Yes | M7: Yes | N7: Yes | O7: Yes | P7: Yes | Q7: Yes | R7: Yes | S7: Yes | T7: Yes | U7: Yes
B8: Members not having taken Information Privacy and Social media guidelines course | C8: Y | D8: Monthly | E8: Number >= 0 | F8: 0 | G8: US Delivery Lead | H8: 0 | I8: 0 | J8: 0 | K8: 0 | L8: 0 | M8: 0 | N8: 0 | O8: 0 | P8: 0 | Q8: 0 | R8: 0 | S8: 0 | T8: 0 | U8: 0
B9: Frequency of formal sync with relevant highest level stakeholder?(in Weeks) | C9: =IF(B2="Team Extension", "N", "Y") -> Y | D9: Monthly | E9: Number >= 0 | F9: 1 | G9: US Delivery Lead | H9: 1 | I9: 1 | J9: 1 | K9: 1 | L9: 1 | M9: 1 | N9: 1 | O9: 1 | P9: 1 | Q9: 1 | R9: 1 | S9: 1 | T9: 1 | U9: 1
B10: Number of client meetings not attended by PM or US Delivery Lead | C10: =IF(B2="Team Extension", "N", "Y") -> Y | D10: Monthly | E10: Number >= 0 | F10: 0 | G10: US Delivery Lead | K10: 0 | L10: 0 | M10: 0 | N10: 0 | O10: 0 | P10: 0 | Q10: 0 | R10: 0 | S10: 0 | T10: 0 | U10: 0
